Workbook

Sheet r_recoleccion
A1: cargado_sql | B1: orden_recoleccion | C1: id_objecto_recoleccion | D1: cantidad_recoleccion | E1: fecha_recoleccion | F1: hora_inicio | G1: hora_fin | H1: categoria_recoleccion | I1: metodo_recoleccion
A2: 1 | B2: 1 | C2: 1 | D2: 55 | E2: 46156 | F2: 0 | G2: 0 | H2: 1 | I2: 0
A3: 1 | B3: 2 | C3: 15 | D3: 1 | E3: 46156 | F3: 0 | G3: 0 | H3: 1 | I3: 0
A4: 1 | B4: 3 | C4: 4 | D4: 10 | E4: 46156 | F4: 0 | G4: 0 | H4: 1 | I4: 0
A5: 1 | B5: 4 | C5: 5 | D5: 12 | E5: 46156 | F5: 0 | G5: 0 | H5: 1 | I5: 0
A6: 1 | B6: 5 | C6: 7 | D6: 1 | E6: 46156 | F6: 0 | G6: 0 | H6: 1 | I6: 0
A7: 1 | B7: 6 | C7: 1 | D7: 22 | E7: 46157 | F7: 0 | G7: 0 | H7: 1 | I7: 0
A8: 1 | B8: 7 | C8: 18 | D8: 1 | E8: 46157 | F8: 0 | G8: 0 | H8: 1 | I8: 0
A9: 1 | B9: 8 | C9: 4 | D9: 5 | E9: 46157 | F9: 0 | G9: 0 | H9: 1 | I9: 0
A10: 1 | B10: 9 | C10: 5 | D10: 6 | E10: 46157 | F10: 0 | G10: 0 | H10: 1 | I10: 0
A11: 1 | B11: 10 | C11: 1 | D11: 21 | E11: 46158 | F11: 0 | G11: 0 | H11: 1 | I11: 0
A12: 1 | B12: 11 | C12: 4 | D12: 5 | E12: 46158 | F12: 0 | G12: 0 | H12: 1 | I12: 0
A13: 1 | B13: 12 | C13: 5 | D13: 4 | E13: 46158 | F13: 0 | G13: 0 | H13: 1 | I13: 0
... A118: 0 | B118: 117 | C118: 27 | D118: 4 | E118: 46190 | F118: 0 | G118: 0 | H118: 2 | I118: 0

Sheet d_tipo_recoleccion
A1: id_tipo_recoleccion | B1: tipo_recoleccion
A2: 0 | B2: pasivo
A3: 1 | B3: activo

Sheet r_consumos_objectos
A1: cargado_sql | B1: orden_consumos_objectos | C1: id_consumos_objectos | D1: consumos_objectos_cantidad | E1: obtengo_consumos_objectos_id | F1: obtengo_consumos_objectos_cantidad | G1: fecha_consumos_objectos | H1: categoria_consumos_objectos
A2: 1 | B2: 1 | C2: 1 | D2: 12 | E2: 101 | F2: 12 | G2: 46157 | H2: 10
A3: 1 | B3: 2 | C3: 4 | D3: 20 | E3: 104 | F3: 2 | G3: 46159 | H3: 10
A4: 1 | B4: 3 | C4: 5 | D4: 20 | E4: 105 | F4: 2 | G4: 46159 | H4: 10
A5: 1 | B5: 4 | C5: 4 | D5: 40 | E5: 104 | F5: 4 | G5: 46160 | H5: 10
A6: 1 | B6: 5 | C6: 5 | D6: 10 | E6: 105 | F6: 1 | G6: 46160 | H6: 10
A7: 1 | B7: 6 | C7: 4 | D7: 40 | E7: 104 | F7: 4 | G7: 46160 | H7: 10
A8: 1 | B8: 7 | C8: 6 | D8: 30 | E8: 106 | F8: 3 | G8: 46160 | H8: 10
A9: 1 | B9: 8 | C9: 4 | D9: 50 | E9: 104 | F9: 5 | G9: 46161 | H9: 10
A10: 1 | B10: 9 | C10: 6 | D10: 40 | E10: 106 | F10: 4 | G10: 46161 | H10: 10
A11: 1 | B11: 10 | C11: 5 | D11: 10 | E11: 105 | F11: 1 | G11: 46161 | H11: 10
A12: 1 | B12: 11 | C12: 12 | D12: 1 | E12: 901 | F12: 1 | G12: 46161 | H12: 11
A13: 1 | B13: 12 | C13: 15 | D13: 1 | E13: 901 | F13: 1 | G13: 46161 | H13: 11
... A96: 0 | B96: 95 | C96: 18 | D96: 1 | E96: 901 | F96: 0 | G96: 46191 | H96: 11

Sheet d_id_objectos
A1: id_objectos | B1: nombre_objectos | C1: Categoria_objectos
A2: 1 | B2: mena de cobalto | C2: mineral
A3: 2 | B3: mena de saronita | C3: mineral
A4: 3 | B4: mena de titanio | C4: mineral
A5: 4 | B5: tierra cristalizada | C5: elemental
A6: 5 | B6: agua cristalizada | C6: elemental
A7: 6 | B7: sombra cristalizada | C7: elemental
A8: 7 | B8: fuego cristalizado | C8: elemental
A9: 8 | B9: aire cristalizado | C9: elemental
A10: 9 | B10: gema roja | C10: gema
A11: 10 | B11: gema roja rara | C11: gema
A12: 11 | B12: gema roja epica | C12: gema
A13: 12 | B13: gema azul | C13: gema
... A59: 904 | B59: blindaje de titanio | C59: mejora

Sheet r_gasto
A1: cargado_sql | B1: orden_gasto | C1: gasto_id | D1: gasto_cantidad | E1: gasto_precio | F1: gasto_fecha
A2: 1 | B2: 1 | C2: 800 | D2: 1 | E2: 10000000 | F2: 46164
A3: 1 | B3: 2 | C3: 300 | D3: 2 | E3: 470000 | F3: 46165
A4: 1 | B4: 3 | C4: 27 | D4: 5 | E4: 1000000 | F4: 46165
A5: 1 | B5: 4 | C5: 902 | D5: 1 | E5: 2500000 | F5: 46166
A6: 1 | B6: 5 | C6: 29 | D6: 1 | E6: 1500000 | F6: 46166
A7: 1 | B7: 6 | C7: 128 | D7: 4 | E7: 1900000 | F7: 46166
A8: 1 | B8: 7 | C8: 27 | D8: 1 | E8: 300000 | F8: 46168
A9: 1 | B9: 8 | C9: 904 | D9: 1 | E9: 2110000 | F9: 46168
A10: 1 | B10: 9 | C10: 27 | D10: 2 | E10: 480000 | F10: 46170
A11: 1 | B11: 10 | C11: 27 | D11: 2 | E11: 1450000 | F11: 46172
A12: 1 | B12: 11 | C12: 27 | D12: 4 | E12: 1040000 | F12: 46177
A13: 1 | B13: 12 | C13: 27 | D13: 9 | E13: 2600000 | F13: 46181
A14: 1 | B14: 13 | C14: 800 | D14: 1 | E14: 14000000 | F14: 46185

Sheet r_registro_poblacion
A1: cargado_sql | B1: orden_poblacion | C1: fecha_poblacion | D1: hora_poblacion | E1: total_poblacion | F1: poblacion_80
A2: 1 | B2: 1 | C2: 46157 | D2: 0.38472222 | E2: 205 | F2: 114
A3: 1 | B3: 2 | C3: 46157 | D3: 0.45208333 | E3: 408 | F3: 206
A4: 1 | B4: 3 | C4: 46157 | D4: 0.58888889 | E4: 535 | F4: 300
A5: 1 | B5: 4 | C5: 46157 | D5: 0.82847222 | E5: 1101 | F5: 578
A6: 1 | B6: 5 | C6: 46157 | D6: 0.95833333 | E6: 1411 | F6: 828
A7: 1 | B7: 6 | C7: 46158 | D7: 0.094444444 | E7: 892 | F7: 423
A8: 1 | B8: 7 | C8: 46158 | D8: 0.60277778 | E8: 886 | F8: 478
A9: 1 | B9: 8 | C9: 46158 | D9: 0.86388889 | E9: 1242 | F9: 699
A10: 1 | B10: 9 | C10: 46158 | D10: 0.975 | E10: 1555 | F10: 936
A11: 1 | B11: 10 | C11: 46159 | D11: 0.1375 | E11: 800 | F11: 456
A12: 1 | B12: 11 | C12: 46159 | D12: 0.54861111 | E12: 744 | F12: 406
A13: 1 | B13: 12 | C13: 46159 | D13: 0.91597222 | E13: 1607 | F13: 955
... A95: 0 | B95: 94 | C95: 46191 | D95: 0.48958333 | E95: 397 | F95: 256

Sheet r_prospeccion_lotes
A1: cargado_sql | B1: orden_prospeccion_lotes | C1: id_mineral_prospeccion_lotes | D1: cantidad_menas_prospeccion_lotes | E1: fecha_prospeccion_lotes
A2: 1 | B2: 1 | C2: 1 | D2: 220 | E2: 46161
A3: 1 | B3: 2 | C3: 2 | D3: 355 | E3: 46163
A4: 1 | B4: 3 | C4: 30 | D4: 1 | E4: 46165
A5: 1 | B5: 4 | C5: 30 | D5: 1 | E5: 46166
A6: 1 | B6: 5 | C6: 30 | D6: 1 | E6: 46167
A7: 1 | B7: 6 | C7: 30 | D7: 1 | E7: 46168
A8: 1 | B8: 7 | C8: 30 | D8: 1 | E8: 46169
A9: 1 | B9: 8 | C9: 30 | D9: 1 | E9: 46170
A10: 1 | B10: 9 | C10: 30 | D10: 1 | E10: 46171
A11: 1 | B11: 10 | C11: 30 | D11: 1 | E11: 46172
A12: 1 | B12: 11 | C12: 30 | D12: 1 | E12: 46173
A13: 1 | B13: 12 | C13: 30 | D13: 1 | E13: 46174
... A30: 0 | B30: 29 | C30: 30 | D30: 1 | E30: 46191

Sheet r_prospeccion_resultados
A1: cargado_sql | B1: orden_prospeccion_resultados | C1: lote_prospeccion_resultados | D1: id_gema_prospeccion_resultados | E1: cantidad_prospeccion_resultados
A2: 1 | B2: 1 | C2: 1 | D2: 9 | E2: 9
A3: 1 | B3: 2 | C3: 1 | D3: 21 | E3: 8
A4: 1 | B4: 3 | C4: 1 | D4: 18 | E4: 7
A5: 1 | B5: 4 | C5: 1 | D5: 15 | E5: 14
A6: 1 | B6: 5 | C6: 1 | D6: 24 | E6: 8
A7: 1 | B7: 6 | C7: 1 | D7: 12 | E7: 11
A8: 1 | B8: 7 | C8: 1 | D8: 13 | E8: 2
A9: 1 | B9: 8 | C9: 1 | D9: 25 | E9: 2
A10: 1 | B10: 9 | C10: 2 | D10: 9 | E10: 29
A11: 1 | B11: 10 | C11: 2 | D11: 12 | E11: 19
A12: 1 | B12: 11 | C12: 2 | D12: 15 | E12: 25
A13: 1 | B13: 12 | C13: 2 | D13: 18 | E13: 45
... A84: 0 | B84: 83 | C84: 29 | D84: 22 | E84: 1

Sheet r_gemas_pulidas
A1: cargado_sql | B1: orden_gemas_pulidas | C1: id_gemas_pulidas | D1: cantidad_gemas_pulidas | E1: atributos_1_gemas_pulidas | F1: atributos_2_gemas_pulidas | G1: fecha_gemas_pulidas
A2: 1 | B2: 1 | C2: 15 | D2: 4 | E2: 9 | F2: 0 | G2: 46161
A3: 1 | B3: 2 | C3: 15 | D3: 3 | E3: 11 | F3: 0 | G3: 46161
A4: 1 | B4: 3 | C4: 18 | D4: 6 | E4: 6 | F4: 5 | G4: 46161
A5: 1 | B5: 4 | C5: 18 | D5: 3 | E5: 7 | F5: 3 | G5: 46161
A6: 1 | B6: 5 | C6: 21 | D6: 4 | E6: 6 | F6: 4 | G6: 46161
A7: 1 | B7: 6 | C7: 21 | D7: 4 | E7: 7 | F7: 8 | G7: 46161
A8: 1 | B8: 7 | C8: 300 | D8: 2 | E8: 51 | F8: 0 | G8: 46165
A9: 1 | B9: 8 | C9: 15 | D9: 5 | E9: 13 | F9: 0 | G9: 46166
A10: 1 | B10: 9 | C10: 24 | D10: 2 | E10: 13 | F10: 4 | G10: 46166

Sheet d_gemas_atributos
A1: id_gemas_atributos | B1: gemas_atributos | C1: nombre_gemas_atributos
A2: 0 | B2: nada | C2: nada
A3: 1 | B3: fuerza | C3: propiedades
A4: 2 | B4: agilidad | C4: propiedades
A5: 3 | B5: aguante | C5: propiedades
A6: 4 | B6: intelecto | C6: propiedades
A7: 5 | B7: espiritu | C7: propiedades
A8: 6 | B8: poder con hechizos | C8: propiedades
A9: 7 | B9: poder de ataque | C9: propiedades
A10: 8 | B10: indice de golpe critico | C10: propiedades
A11: 9 | B11: indice de celeridad | C11: propiedades
A12: 10 | B12: indice de penetracion de armadura | C12: propiedades
A13: 11 | B13: indice de golpe | C13: propiedades
... A57: 55 | B57: +25 poder con hechizos y 10% menos duracion de stun | C57: diamante de asedio de tierra penetrante

Sheet r_consumo_lotes
A1: cargado_sql | B1: orden_consumo_lotes | C1: id_consumo_lotes | D1: cantidad_consumo_lotes | E1: fecha_consumo_lotes
A2: 1 | B2: 1 | C2: 8 | D2: 5 | E2: 46166
A3: 1 | B3: 2 | C3: 9 | D3: 2 | E3: 46166

Sheet r_venta_gemas
A1: cargado_sql | B1: orden_venta_gemas | C1: orden_pulida_venta_gemas | D1: id_valor_venta_gemas | E1: tiempo_venta_gemas | F1: precio_deposito_venta_gemas | G1: valor_venta_gemas | H1: estado_venta_gemas | I1: resultado_venta_gemas | J1: fecha_venta_gemas | K1: hora_venta_gemas | L1: metodo_venta_gemas
A2: 1 | B2: 1 | C2: 1 | D2: 1 | E2: 12 | F2: =INT(VLOOKUP(D2,d_gema_valor!$A$2:$C$5,3,FALSE) * VLOOKUP(E2,d_deposito!$A$2:$B$5,2,FALSE)) -> 187 | G2: 39800 | H2: 1 | I2: =IF(H2=1, IF(L2=1, INT(G2 * (1 - VALUE(SUBSTITUTE(d_correo!$B$2, ",", ".")))), G2), -F2) -> 39501 | J2: 46162 | K2: 0.46527778 | L2: 1
A3: 1 | B3: 2 | C3: 1 | D3: 1 | E3: 12 | F3: =INT(VLOOKUP(D3,d_gema_valor!$A$2:$C$5,3,FALSE) * VLOOKUP(E3,d_deposito!$A$2:$B$5,2,FALSE)) -> 187 | G3: 39800 | H3: 2 | I3: =IF(H3=1, IF(L3=1, INT(G3 * (1 - VALUE(SUBSTITUTE(d_correo!$B$2, ",", ".")))), G3), -F3) -> -187 | J3: 46162 | K3: 0.46527778 | L3: 1
A4: 1 | B4: 3 | C4: 1 | D4: 1 | E4: 12 | F4: =INT(VLOOKUP(D4,d_gema_valor!$A$2:$C$5,3,FALSE) * VLOOKUP(E4,d_deposito!$A$2:$B$5,2,FALSE)) -> 187 | G4: 39800 | H4: 2 | I4: =IF(H4=1, IF(L4=1, INT(G4 * (1 - VALUE(SUBSTITUTE(d_correo!$B$2, ",", ".")))), G4), -F4) -> -187 | J4: 46162 | K4: 0.46527778 | L4: 1
A5: 1 | B5: 4 | C5: 1 | D5: 1 | E5: 12 | F5: =INT(VLOOKUP(D5,d_gema_valor!$A$2:$C$5,3,FALSE) * VLOOKUP(E5,d_deposito!$A$2:$B$5,2,FALSE)) -> 187 | G5: 39800 | H5: 2 | I5: =IF(H5=1, IF(L5=1, INT(G5 * (1 - VALUE(SUBSTITUTE(d_correo!$B$2, ",", ".")))), G5), -F5) -> -187 | J5: 46162 | K5: 0.46527778 | L5: 1
A6: 1 | B6: 5 | C6: 2 | D6: 1 | E6: 12 | F6: =INT(VLOOKUP(D6,d_gema_valor!$A$2:$C$5,3,FALSE) * VLOOKUP(E6,d_deposito!$A$2:$B$5,2,FALSE)) -> 187 | G6: 49800 | H6: 1 | I6: =IF(H6=1, IF(L6=1, INT(G6 * (1 - VALUE(SUBSTITUTE(d_correo!$B$2, ",", ".")))), G6), -F6) -> 49426 | J6: 46162 | K6: 0.46527778 | L6: 1
A7: 1 | B7: 6 | C7: 2 | D7: 1 | E7: 12 | F7: =INT(VLOOKUP(D7,d_gema_valor!$A$2:$C$5,3,FALSE) * VLOOKUP(E7,d_deposito!$A$2:$B$5,2,FALSE)) -> 187 | G7: 49800 | H7: 1 | I7: =IF(H7=1, IF(L7=1, INT(G7 * (1 - VALUE(SUBSTITUTE(d_correo!$B$2, ",", ".")))), G7), -F7) -> 49426 | J7: 46162 | K7: 0.46527778 | L7: 1
A8: 1 | B8: 7 | C8: 2 | D8: 1 | E8: 12 | F8: =INT(VLOOKUP(D8,d_gema_valor!$A$2:$C$5,3,FALSE) * VLOOKUP(E8,d_deposito!$A$2:$B$5,2,FALSE)) -> 187 | G8: 49800 | H8: 1 | I8: =IF(H8=1, IF(L8=1, INT(G8 * (1 - VALUE(SUBSTITUTE(d_correo!$B$2, ",", ".")))), G8), -F8) -> 49426 | J8: 46162 | K8: 0.46527778 | L8: 1
A9: 1 | B9: 8 | C9: 3 | D9: 1 | E9: 12 | F9: =INT(VLOOKUP(D9,d_gema_valor!$A$2:$C$5,3,FALSE) * VLOOKUP(E9,d_deposito!$A$2:$B$5,2,FALSE)) -> 187 | G9: 50000 | H9: 2 | I9: =IF(H9=1, IF(L9=1, INT(G9 * (1 - VALUE(SUBSTITUTE(d_correo!$B$2, ",", ".")))), G9), -F9) -> -187 | J9: 46162 | K9: 0.46527778 | L9: 1
A10: 1 | B10: 9 | C10: 3 | D10: 1 | E10: 12 | F10: =INT(VLOOKUP(D10,d_gema_valor!$A$2:$C$5,3,FALSE) * VLOOKUP(E10,d_deposito!$A$2:$B$5,2,FALSE)) -> 187 | G10: 50000 | H10: 2 | I10: =IF(H10=1, IF(L10=1, INT(G10 * (1 - VALUE(SUBSTITUTE(d_correo!$B$2, ",", ".")))), G10), -F10) -> -187 | J10: 46162 | K10: 0.46527778 | L10: 1
A11: 1 | B11: 10 | C11: 3 | D11: 1 | E11: 12 | F11: =INT(VLOOKUP(D11,d_gema_valor!$A$2:$C$5,3,FALSE) * VLOOKUP(E11,d_deposito!$A$2:$B$5,2,FALSE)) -> 187 | G11: 50000 | H11: 2 | I11: =IF(H11=1, IF(L11=1, INT(G11 * (1 - VALUE(SUBSTITUTE(d_correo!$B$2, ",", ".")))), G11), -F11) -> -187 | J11: 46162 | K11: 0.46527778 | L11: 1
A12: 1 | B12: 11 | C12: 3 | D12: 1 | E12: 12 | F12: =INT(VLOOKUP(D12,d_gema_valor!$A$2:$C$5,3,FALSE) * VLOOKUP(E12,d_deposito!$A$2:$B$5,2,FALSE)) -> 187 | G12: 50000 | H12: 2 | I12: =IF(H12=1, IF(L12=1, INT(G12 * (1 - VALUE(SUBSTITUTE(d_correo!$B$2, ",", ".")))), G12), -F12) -> -187 | J12: 46162 | K12: 0.46527778 | L12: 1
A13: 1 | B13: 12 | C13: 3 | D13: 1 | E13: 12 | F13: =INT(VLOOKUP(D13,d_gema_valor!$A$2:$C$5,3,FALSE) * VLOOKUP(E13,d_deposito!$A$2:$B$5,2,FALSE)) -> 187 | G13: 50000 | H13: 2 | I13: =IF(H13=1, IF(L13=1, INT(G13 * (1 - VALUE(SUBSTITUTE(d_correo!$B$2, ",", ".")))), G13), -F13) -> -187 | J13: 46162 | K13: 0.46527778 | L13: 1
... A114: 1 | B114: 113 | C114: 7 | D114: 4 | E114: 12 | F114: =INT(VLOOKUP(D114,d_gema_valor!$A$2:$C$5,3,FALSE) * VLOOKUP(E114,d_deposito!$A$2:$B$5,2,FALSE)) -> 2250 | G114: 699900 | H114: 2 | I114: =IF(H114=1, IF(L114=1, INT(G114 * (1 - VALUE(SUBSTITUTE(d_correo!$B$2, ",", ".")))), G114), -F114) -> -2250 | J114: 46171 | K114: 0.85069444 | L114: 1

Sheet d_venta_estado
A1: id_venta_estado | B1: venta_estado
A2: 0 | B2: pendiente
A3: 1 | B3: vendido
A4: 2 | B4: expirado
A5: 3 | B5: cancelado

Sheet d_venta_metodo
A1: id_venta_metodo | B1: venta_metodo
A2: 1 | B2: subasta
A3: 2 | B3: servicio
A4: 3 | B4: regalo

Sheet d_gema_valor
A1: id_gema_valor | B1: calidad_gema_valor | C1: precio_valor_cobre
A2: 1 | B2: comun | C2: 5000
A3: 2 | B3: rara | C3: 45000
A4: 3 | B4: epica | C4: 90000
A5: 4 | B5: meta | C5: 60000

Sheet r_valor_subasta
A1: cargado_sql | B1: orden_valor_subasta | C1: id_objecto_valor_subasta | D1: precio_valor_subasta | E1: fecha_valor_subasta | F1: hora_valor_subasta
A2: 1 | B2: 1 | C2: 9 | D2: 8800 | E2: 46162 | F2: 0.45625
A3: 1 | B3: 2 | C3: 12 | D3: 11950 | E3: 46162 | F3: 0.45625
A4: 1 | B4: 3 | C4: 15 | D4: 12000 | E4: 46162 | F4: 0.45625
A5: 1 | B5: 4 | C5: 18 | D5: 11500 | E5: 46162 | F5: 0.45625
A6: 1 | B6: 5 | C6: 21 | D6: 12000 | E6: 46162 | F6: 0.45625
A7: 1 | B7: 6 | C7: 24 | D7: 4995 | E7: 46162 | F7: 0.45625
A8: 1 | B8: 7 | C8: 9 | D8: 4600 | E8: 46164 | F8: 0.41319444
A9: 1 | B9: 8 | C9: 12 | D9: 15800 | E9: 46164 | F9: 0.41319444
A10: 1 | B10: 9 | C10: 15 | D10: 7200 | E10: 46164 | F10: 0.41319444
A11: 1 | B11: 10 | C11: 18 | D11: 2400 | E11: 46164 | F11: 0.41319444
A12: 1 | B12: 11 | C12: 21 | D12: 5400 | E12: 46164 | F12: 0.41319444
A13: 1 | B13: 12 | C13: 24 | D13: 2400 | E13: 46164 | F13: 0.41319444
... A73: 1 | B73: 72 | C73: 103 | D73: 86030 | E73: 46173 | F73: 0.076099537
A74: 1 | B74: 73 | C74: 1 | D74: 14600 | E74: 31/05/2026 | F74: 14:40:32
A75: 1 | B75: 74 | C75: 2 | D75: 8400 | E75: 31/05/2026 | F75: 14:40:32
A76: 1 | B76: 75 | C76: 3 | D76: 82500 | E76: 31/05/2026 | F76: 14:40:32
A77: 1 | B77: 76 | C77: 9 | D77: 11600 | E77: 31/05/2026 | F77: 14:40:32
A78: 1 | B78: 77 | C78: 10 | D78: 589000 | E78: 31/05/2026 | F78: 14:40:32
A79: 1 | B79: 78 | C79: 11 | D79: 807692 | E79: 31/05/2026 | F79: 14:40:32
A80: 1 | B80: 79 | C80: 12 | D80: 18800 | E80: 31/05/2026 | F80: 14:40:32
A81: 1 | B81: 80 | C81: 13 | D81: 44800 | E81: 31/05/2026 | F81: 14:40:32
A82: 1 | B82: 81 | C82: 14 | D82: 750000 | E82: 31/05/2026 | F82: 14:40:32
A83: 1 | B83: 82 | C83: 15 | D83: 9000 | E83: 31/05/2026 | F83: 14:40:32
A84: 1 | B84: 83 | C84: 16 | D84: 138500 | E84: 31/05/2026 | F84: 14:40:32
A85: 1 | B85: 84 | C85: 17 | D85: 872625 | E85: 31/05/2026 | F85: 14:40:32
... A97: 1 | B97: 96 | C97: 103 | D97: 86030 | E97: 31/05/2026 | F97: 14:40:32
A98: 1 | B98: 97 | C98: 1 | D98: 13000 | E98: 46173 | F98: 0.86100694
A99: 1 | B99: 98 | C99: 2 | D99: 8400 | E99: 46173 | F99: 0.86100694
A100: 1 | B100: 99 | C100: 3 | D100: 100000 | E100: 46173 | F100: 0.86100694
A101: 1 | B101: 100 | C101: 9 | D101: 9900 | E101: 46173 | F101: 0.86100694
A102: 1 | B102: 101 | C102: 10 | D102: 898000 | E102: 46173 | F102: 0.86100694
A103: 1 | B103: 102 | C103: 11 | D103: 807692 | E103: 46173 | F103: 0.86100694
A104: 1 | B104: 103 | C104: 12 | D104: 18599 | E104: 46173 | F104: 0.86100694
A105: 1 | B105: 104 | C105: 13 | D105: 44800 | E105: 46173 | F105: 0.86100694
A106: 1 | B106: 105 | C106: 14 | D106: 750000 | E106: 46173 | F106: 0.86100694
A107: 1 | B107: 106 | C107: 15 | D107: 9000 | E107: 46173 | F107: 0.86100694
A108: 1 | B108: 107 | C108: 16 | D108: 138500 | E108: 46173 | F108: 0.86100694
A109: 1 | B109: 108 | C109: 17 | D109: 872625 | E109: 46173 | F109: 0.86100694
... A121: 1 | B121: 120 | C121: 103 | D121: 86030 | E121: 46173 | F121: 0.86100694
...

Sheet d_deposito
A1: tiempo_deposito | B1: porcentaje_deposito
A2: 0 | B2: 0
A3: 12 | B3: 0.0375
A4: 24 | B4: 0.075
A5: 48 | B5: 0.15

Sheet d_correo
A1: id_correo | B1: comision
A2: 1 | B2: 0.0075

Sheet d_convertibilidad
A1: convertibilidad_moneda | B1: convertibilidad_valor_cobre
A2: cobre | B2: 1
A3: plata | B3: 100
A4: oro | B4: 10000

Sheet d_recetas_id
A1: id_recetas | B1: recetas_nombre | C1: categoria_recetas_id
A2: 1 | B2: prisma helado | C2: 3
A3: 100 | B3: anillo de guardian de tierra de titanio | C3: 101
A4: 200 | B4: titanio | C4: 200
A5: 201 | B5: rubi cardeno | C5: 200
A6: 202 | B6: ametrino | C6: 200
A7: 203 | B7: piedra de terror | C7: 200
A8: 204 | B8: ojo de zul | C8: 200
A9: 205 | B9: ambar del rey | C9: 200
A10: 206 | B10: circon majestuoso | C10: 200
A11: 207 | B11: diamante de asedio de tierra | C11: 200
A12: 208 | B12: diamante de llama celeste | C12: 200
A13: 800 | B13: sortija de sangrita | C13: 101
... A15: 802 | B15: cangrejo monarca | C15: 103

Sheet d_recetas_materiales
A1: id_recetas_materiales | B1: id_objectos_receta_materiales | C1: cantidad_recetas_materiales
A2: 800 | B2: 4 | C2: 2
A3: 800 | B3: 9 | C3: 1
A4: 801 | B4: 104 | C4: 1
A5: 801 | B5: 106 | C5: 1
A6: 802 | B6: 104 | C6: 2
A7: 1 | B7: 27 | C7: 1
A8: 1 | B8: 12 | C8: 1
A9: 1 | B9: 18 | C9: 1
A10: 1 | B10: 24 | C10: 1
A11: 802 | B11: 103 | C11: 2
A12: 802 | B12: 22 | C12: 2
A13: 802 | B13: 25 | C13: 1
... A36: 208 | B36: 108 | C36: 1

Sheet r_recetas_consumo
A1: cargado_sql | B1: orden_recetas_consumo | C1: id_recetas_consumo | D1: cantidad_recetas_consumo | E1: fecha_recetas_consumo
A2: 1 | B2: 1 | C2: 800 | D2: 3 | E2: 46163
A3: 1 | B3: 2 | C3: 801 | D3: 8 | E3: 46163
A4: 1 | B4: 3 | C4: 801 | D4: 4 | E4: 46164
A5: 1 | B5: 4 | C5: 1 | D5: 1 | E5: 46165
A6: 1 | B6: 5 | C6: 1 | D6: 1 | E6: 46166
A7: 1 | B7: 6 | C7: 802 | D7: 1 | E7: 46166
A8: 1 | B8: 7 | C8: 100 | D8: 1 | E8: 46166
A9: 1 | B9: 8 | C9: 1 | D9: 1 | E9: 46167
A10: 1 | B10: 9 | C10: 1 | D10: 1 | E10: 46168
A11: 1 | B11: 10 | C11: 1 | D11: 1 | E11: 46169
A12: 1 | B12: 11 | C12: 1 | D12: 1 | E12: 46170
A13: 1 | B13: 12 | C13: 1 | D13: 1 | E13: 46171
... A33: 0 | B33: 32 | C33: 1 | D33: 1 | E33: 46191

Sheet d_categoria_producto
A1: id_categoria_producto | B1: categoria_producto_nombre
A2: 1 | B2: mineria
A3: 2 | B3: botin
A4: 3 | B4: joyeria
A5: 10 | B5: fabricacion
A6: 11 | B6: mision
A7: 101 | B7: anillo
A8: 102 | B8: collar
A9: 103 | B9: abalorio
A10: 200 | B10: transmutacion

Sheet r_transmutaciones
A1: cargado_sql | B1: orden_transmutaciones | C1: receta_transmutaciones | D1: cantidad_transmutaciones | E1: fecha_transmutaciones
A2: 1 | B2: 1 | C2: 200 | D2: 23 | E2: 46179

Sheet r_transmutaciones_resultados
A1: cargado_sql | B1: orden_transmutaciones_resultados | C1: orden_transmutacion | D1: obtengo_objecto_transmutaciones_resultados | E1: obtengo_cantidad_transmutaciones_resultados
A2: 1 | B2: 1 | C2: 1 | D2: 103 | E2: 26
